<?xml version="1.0"?>

<robot xmlns:xacro="http://www.ros.org/wiki/xacro" name="caster_bottom_flat">
    <xacro:property name="cbf_scale" value="0.026"/>
    <xacro:macro name="caster_bottom_flat" params="prefix reflect reflect_x">
        <link name="${prefix}_bottom_flat">
            <visual>
                <origin xyz="0 0 0" rpy="0 0 0"/>
                <geometry>
                    <mesh filename="package://rabbitamr_description/meshes/caster_wheel/bottom_flat.stl" scale="${cbf_scale} ${cbf_scale} ${cbf_scale}"/>
                </geometry>
                <material name="white"/>
            </visual>
            <collision>
                <origin xyz="0 0 0" rpy="0 0 0"/>
                <geometry>
                    <mesh filename="package://rabbitamr_description/meshes/caster_wheel/bottom_flat.stl" scale="${cbf_scale} ${cbf_scale} ${cbf_scale}"/>
                </geometry>
            </collision>
            <xacro:box_inertia m="1" w="0.001" h="0.001" d="0.001"/>
        </link>

        <joint name="${prefix}_bottom_flat_joint" type="continuous">
            <axis xyz="0 0 1" rpy="0 0 0"/>
            <parent link="${prefix}_mechanism_bottom"/>
            <child link="${prefix}_bottom_flat"/>
            <origin xyz="0 0 0.0026" rpy="0 0 0"/>
        </joint>
    </xacro:macro>
</robot>