<?xml version="1.0" encoding="utf-8"?>
<!-- =================================================================================== -->
<!-- |    This document was autogenerated by xacro from rabbitamr.urdf.xacro             | -->
<!-- |    EDITING THIS FILE BY HAND IS NOT RECOMMENDED                                 | -->
<!-- =================================================================================== -->
<robot name="rabbitamr">
  <gazebo reference="base_link">
    <material>Gazebo/Blue</material>
  </gazebo>
  <gazebo reference="sicklidar">
    <material>Gazebo/Black</material>
  </gazebo>
  <gazebo reference="left_wheel">
    <material>Gazebo/Orange</material>
  </gazebo>
  <gazebo reference="right_wheel">
    <material>Gazebo/Orange</material>
  </gazebo>
  <gazebo reference="front_left_caster_wheel">
    <material>Gazebo/Red</material>
  </gazebo>
  <gazebo reference="front_right_caster_wheel">
    <material>Gazebo/Red</material>
  </gazebo>
  <gazebo reference="back_left_caster_wheel">
    <material>Gazebo/Red</material>
  </gazebo>
  <gazebo reference="back_right_caster_wheel">
    <material>Gazebo/Red</material>
  </gazebo>
  <gazebo>
    <plugin name="differential_drive_controller" filename="libgazebo_ros_diff_drive.so">
      <commandTopic>rabbitamr_diff_drive_controller/cmd_vel</commandTopic>
      <odometryTopic>rabbitamr_diff_drive_controller/odom</odometryTopic>
      <odometryFrame>odom</odometryFrame>
      <odometrySource>world</odometrySource>
      <publishOdomTF>true</publishOdomTF>
      <robotBaseFrame>base_footprint</robotBaseFrame>
      <publishWheelTF>false</publishWheelTF>
      <publishTf>true</publishTf>
      <publishWheelJointState>true</publishWheelJointState>
      <legacyMode>false</legacyMode>
      <updateRate>30</updateRate>
      <leftJoint>left_wheel_joint</leftJoint>
      <rightJoint>right_wheel_joint</rightJoint>
      <wheelSeparation>0.62</wheelSeparation>
      <wheelDiameter>0.2</wheelDiameter>
      <wheelAcceleration>1</wheelAcceleration>
      <wheelTorque>5</wheelTorque>
      <rosDebugLevel>na</rosDebugLevel>
    </plugin>
  </gazebo>
  <!-- IMU -->
  <gazebo reference="imu_link">
    <gravity>true</gravity>
    <sensor name="imu_sensor" type="imu">
      <always_on>true</always_on>
      <update_rate>100</update_rate>
      <visualize>true</visualize>
      <topic>__default_topic__</topic>
      <plugin filename="libgazebo_ros_imu_sensor.so" name="imu_plugin">
        <topicName>imu/data</topicName>
        <bodyName>imu_link</bodyName>
        <updateRateHZ>10.0</updateRateHZ>
        <gaussianNoise>0.0</gaussianNoise>
        <xyzOffset>0 0 0</xyzOffset>
        <rpyOffset>0 0 0</rpyOffset>
        <frameName>imu_link</frameName>
        <initialOrientationAsReference>false</initialOrientationAsReference>
      </plugin>
      <pose>0 0 0 0 0 0</pose>
    </sensor>
  </gazebo>
  <!-- Sick Lidar -->
  <gazebo reference="sicklidar">
    <sensor name="head_hokuyo_sensor" type="ray">
      <pose>0 0 0 0 0 0</pose>
      <visualize>true</visualize>
      <update_rate>50</update_rate>
      <ray>
        <scan>
          <horizontal>
            <samples>720</samples>
            <resolution>1</resolution>
            <min_angle>-1.920796</min_angle>
            <max_angle>1.920796</max_angle>
          </horizontal>
        </scan>
        <range>
          <min>0.10</min>
          <max>40.0</max>
          <resolution>0.01</resolution>
        </range>
        <noise>
          <type>gaussian</type>
          <mean>0.0</mean>
          <stddev>0.001</stddev>
        </noise>
      </ray>
      <plugin filename="libgazebo_ros_laser.so" name="gazebo_ros_head_hokuyo_controller">
        <topicName>/sick_safetyscanners/scan</topicName>
        <frameName>sicklidar</frameName>
      </plugin>
    </sensor>
  </gazebo>
  <!-- camera -->
  <gazebo reference="d435i">
    <sensor name="camera" type="depth">
      <always_on>true</always_on>
      <update_rate>20.0</update_rate>
      <camera>
        <horizontal_fov>1.65806</horizontal_fov>
        <image>
          <width>1280</width>
          <height>720</height>
          <format>R8G8B8</format>
        </image>
        <clip>
          <near>0.05</near>
          <far>8</far>
        </clip>
      </camera>
      <plugin filename="libgazebo_ros_openni_kinect.so" name="kinect_camera_controller">
        <cameraName>camera</cameraName>
        <alwaysOn>true</alwaysOn>
        <updateRate>10</updateRate>
        <imageTopicName>rgb/image_raw</imageTopicName>
        <depthImageTopicName>depth/image_raw</depthImageTopicName>
        <pointCloudTopicName>depth/points</pointCloudTopicName>
        <cameraInfoTopicName>rgb/camera_info</cameraInfoTopicName>
        <depthImageCameraInfoTopicName>depth/camera_info</depthImageCameraInfoTopicName>
        <frameName>d435i</frameName>
        <baseline>0.1</baseline>
        <distortion_k1>0.0</distortion_k1>
        <distortion_k2>0.0</distortion_k2>
        <distortion_k3>0.0</distortion_k3>
        <distortion_t1>0.0</distortion_t1>
        <distortion_t2>0.0</distortion_t2>
        <pointCloudCutoff>0.1</pointCloudCutoff>
      </plugin>
    </sensor>
  </gazebo>
  <!--Color Properties-->
  <material name="blue">
    <color rgba="0 0 0.8 1"/>
  </material>
  <material name="black">
    <color rgba="0 0 0 1"/>
  </material>
  <material name="white">
    <color rgba="1 1 1 1"/>
  </material>
  <material name="orange">
    <color rgba="0.5 0.2 0.2 1"/>
  </material>
  <!-- Base footprint is on the ground under the robot -->
  <link name="base_footprint"/>
  <!--Base link-->
  <link name="base_link">
    <inertial>
      <mass value="1"/>
      <inertia ixx="0.0483333333333" ixy="0.0" ixz="0.0" iyy="0.264966666667" iyz="0.0" izz="0.231633333333"/>
    </inertial>
    <visual>
      <geometry>
        <mesh filename="package://rabbitamr_description/meshes/body.stl" scale="0.0001 0.0001 0.0001"/>
      </geometry>
      <material name="blue"/>
    </visual>
    <collision>
      <geometry>
        <mesh filename="package://rabbitamr_description/meshes/body.stl" scale="0.0001 0.0001 0.0001"/>
      </geometry>
    </collision>
  </link>
  <!--base_link - base_footprint Joint-->
  <joint name="base_footprint_joint" type="fixed">
    <origin rpy="0 0 0" xyz="0 0 0.171"/>
    <parent link="base_footprint"/>
    <child link="base_link"/>
  </joint>
  <link name="imu_link"/>
  <joint name="imu_link_joint" type="fixed">
    <origin rpy="0 0 0" xyz="0 0 0"/>
    <parent link="base_link"/>
    <child link="imu_link"/>
  </joint>
  <link name="left_wheel">
    <visual>
      <origin rpy="0 0 0" xyz="0 0 0"/>
      <geometry>
        <mesh filename="package://rabbitamr_description/meshes/wheel.stl" scale="0.0025 0.0025 0.0025"/>
      </geometry>
      <material name="orange"/>
    </visual>
    <collision>
      <origin rpy="1.57079632679 0 0" xyz="0 0 0"/>
      <geometry>
        <cylinder length="0.05" radius="0.1"/>
      </geometry>
    </collision>
    <inertial>
      <mass value="1"/>
      <inertia ixx="0.00270833333333" ixy="0" ixz="0" iyy="0.00270833333333" iyz="0" izz="0.005"/>
    </inertial>
  </link>
  <joint name="left_wheel_joint" type="continuous">
    <axis rpy="0 0 0" xyz="0 1 0"/>
    <parent link="base_link"/>
    <child link="left_wheel"/>
    <origin rpy="0 0 0" xyz="0 0.31 -0.071"/>
  </joint>
  <link name="right_wheel">
    <visual>
      <origin rpy="0 0 0" xyz="0 0 0"/>
      <geometry>
        <mesh filename="package://rabbitamr_description/meshes/wheel.stl" scale="0.0025 0.0025 0.0025"/>
      </geometry>
      <material name="orange"/>
    </visual>
    <collision>
      <origin rpy="1.57079632679 0 0" xyz="0 0 0"/>
      <geometry>
        <cylinder length="0.05" radius="0.1"/>
      </geometry>
    </collision>
    <inertial>
      <mass value="1"/>
      <inertia ixx="0.00270833333333" ixy="0" ixz="0" iyy="0.00270833333333" iyz="0" izz="0.005"/>
    </inertial>
  </link>
  <joint name="right_wheel_joint" type="continuous">
    <axis rpy="0 0 0" xyz="0 1 0"/>
    <parent link="base_link"/>
    <child link="right_wheel"/>
    <origin rpy="0 0 0" xyz="0 -0.31 -0.071"/>
  </joint>
  <link name="front_left_top_flat">
    <visual>
      <origin rpy="0 0 0" xyz="0 0 0"/>
      <geometry>
        <mesh filename="package://rabbitamr_description/meshes/caster_wheel/top_flat.stl" scale="3.9 3.9 3.9"/>
      </geometry>
      <material name="white"/>
    </visual>
    <collision>
      <origin rpy="0 0 0" xyz="0 0 0"/>
      <geometry>
        <box size="0.15 0.15 0.01"/>
      </geometry>
    </collision>
    <inertial>
      <mass value="1"/>
      <inertia ixx="1.66666666667e-07" ixy="0.0" ixz="0.0" iyy="1.66666666667e-07" iyz="0.0" izz="1.66666666667e-07"/>
    </inertial>
  </link>
  <joint name="front_left_top_flat_joint" type="fixed">
    <parent link="base_link"/>
    <child link="front_left_top_flat"/>
    <origin rpy="0 0 0" xyz="0.5125 0.239 0.003525"/>
  </joint>
  <link name="front_left_mechanism_top">
    <visual>
      <origin rpy="0 0 0" xyz="0 0 0"/>
      <geometry>
        <mesh filename="package://rabbitamr_description/meshes/caster_wheel/mechanism_top.stl" scale="0.13 0.13 0.13"/>
      </geometry>
      <material name="white"/>
    </visual>
    <collision>
      <origin rpy="0 0 0" xyz="0 0 0"/>
      <geometry>
        <mesh filename="package://rabbitamr_description/meshes/caster_wheel/mechanism_top.stl" scale="0.13 0.13 0.13"/>
      </geometry>
    </collision>
    <inertial>
      <mass value="1"/>
      <inertia ixx="0.000358333333333" ixy="0" ixz="0" iyy="0.000358333333333" iyz="0" izz="0.00045"/>
    </inertial>
  </link>
  <joint name="front_left_mechanism_top_joint" type="continuous">
    <axis rpy="0 0 0" xyz="0 0 1"/>
    <parent link="front_left_top_flat"/>
    <child link="front_left_mechanism_top"/>
    <origin rpy="0 0 0" xyz="0 0 0"/>
  </joint>
  <link name="front_left_mechanism_bottom">
    <visual>
      <origin rpy="3.14159265359 0 0" xyz="0 0 0"/>
      <geometry>
        <mesh filename="package://rabbitamr_description/meshes/caster_wheel/mechanism_top.stl" scale="0.13 0.13 0.13"/>
      </geometry>
      <material name="white"/>
    </visual>
    <collision>
      <origin rpy="3.14159265359 0 0" xyz="0 0 0"/>
      <geometry>
        <mesh filename="package://rabbitamr_description/meshes/caster_wheel/mechanism_top.stl" scale="0.13 0.13 0.13"/>
      </geometry>
    </collision>
    <inertial>
      <mass value="1"/>
      <inertia ixx="0.000358333333333" ixy="0" ixz="0" iyy="0.000358333333333" iyz="0" izz="0.00045"/>
    </inertial>
  </link>
  <joint name="front_left_mechanism_bottom_joint" type="fixed">
    <parent link="front_left_mechanism_top"/>
    <child link="front_left_mechanism_bottom"/>
    <origin rpy="0 0 0" xyz="0 0.015 -0.0312"/>
  </joint>
  <link name="front_left_bottom_flat">
    <visual>
      <origin rpy="0 0 0" xyz="0 0 0"/>
      <geometry>
        <mesh filename="package://rabbitamr_description/meshes/caster_wheel/bottom_flat.stl" scale="0.026 0.026 0.026"/>
      </geometry>
      <material name="white"/>
    </visual>
    <collision>
      <origin rpy="0 0 0" xyz="0 0 0"/>
      <geometry>
        <mesh filename="package://rabbitamr_description/meshes/caster_wheel/bottom_flat.stl" scale="0.026 0.026 0.026"/>
      </geometry>
    </collision>
    <inertial>
      <mass value="1"/>
      <inertia ixx="1.66666666667e-07" ixy="0.0" ixz="0.0" iyy="1.66666666667e-07" iyz="0.0" izz="1.66666666667e-07"/>
    </inertial>
  </link>
  <joint name="front_left_bottom_flat_joint" type="continuous">
    <axis rpy="0 0 0" xyz="0 0 1"/>
    <parent link="front_left_mechanism_bottom"/>
    <child link="front_left_bottom_flat"/>
    <origin rpy="0 0 0" xyz="0 0 0.0026"/>
  </joint>
  <link name="front_left_wheel_holder">
    <visual>
      <origin rpy="0 0 0" xyz="0 0 0"/>
      <geometry>
        <mesh filename="package://rabbitamr_description/meshes/caster_wheel/wheel_holder.stl" scale="0.1014 0.1014 0.1014"/>
      </geometry>
      <material name="white"/>
    </visual>
    <collision>
      <origin rpy="0 0 0" xyz="0 0 0"/>
      <geometry>
        <mesh filename="package://rabbitamr_description/meshes/caster_wheel/wheel_holder.stl" scale="0.1014 0.1014 0.1014"/>
      </geometry>
    </collision>
    <inertial>
      <mass value="1"/>
      <inertia ixx="1.66666666667e-07" ixy="0.0" ixz="0.0" iyy="1.66666666667e-07" iyz="0.0" izz="1.66666666667e-07"/>
    </inertial>
  </link>
  <joint name="front_left_wheel_holder_joint" type="fixed">
    <axis rpy="0 0 0" xyz="0 0 1"/>
    <parent link="front_left_bottom_flat"/>
    <child link="front_left_wheel_holder"/>
    <origin rpy="0 0 0" xyz="0 0 -0.0494"/>
  </joint>
  <link name="front_left_caster_wheel">
    <visual>
      <origin rpy="0 0 0" xyz="0 0 0"/>
      <geometry>
        <mesh filename="package://rabbitamr_description/meshes/caster_wheel/caster_wheel.stl" scale="0.1014 0.1014 0.1014"/>
      </geometry>
      <material name="orange"/>
    </visual>
    <collision>
      <origin rpy="1.57079632679 0 0" xyz="0 0 0"/>
      <geometry>
        <cylinder length="0.03" radius="0.05"/>
      </geometry>
    </collision>
    <inertial>
      <mass value="1"/>
      <inertia ixx="0.000358333333333" ixy="0" ixz="0" iyy="0.000358333333333" iyz="0" izz="0.00045"/>
    </inertial>
  </link>
  <joint name="front_left_caster_wheel_joint" type="continuous">
    <axis rpy="0 0 0" xyz="0 1 0"/>
    <parent link="front_left_wheel_holder"/>
    <child link="front_left_caster_wheel"/>
    <origin rpy="0 0 0" xyz="0.0195 0 -0.044525"/>
  </joint>
  <link name="front_right_top_flat">
    <visual>
      <origin rpy="0 0 0" xyz="0 0 0"/>
      <geometry>
        <mesh filename="package://rabbitamr_description/meshes/caster_wheel/top_flat.stl" scale="3.9 3.9 3.9"/>
      </geometry>
      <material name="white"/>
    </visual>
    <collision>
      <origin rpy="0 0 0" xyz="0 0 0"/>
      <geometry>
        <box size="0.15 0.15 0.01"/>
      </geometry>
    </collision>
    <inertial>
      <mass value="1"/>
      <inertia ixx="1.66666666667e-07" ixy="0.0" ixz="0.0" iyy="1.66666666667e-07" iyz="0.0" izz="1.66666666667e-07"/>
    </inertial>
  </link>
  <joint name="front_right_top_flat_joint" type="fixed">
    <parent link="base_link"/>
    <child link="front_right_top_flat"/>
    <origin rpy="0 0 0" xyz="0.5125 -0.239 0.003525"/>
  </joint>
  <link name="front_right_mechanism_top">
    <visual>
      <origin rpy="0 0 0" xyz="0 0 0"/>
      <geometry>
        <mesh filename="package://rabbitamr_description/meshes/caster_wheel/mechanism_top.stl" scale="0.13 0.13 0.13"/>
      </geometry>
      <material name="white"/>
    </visual>
    <collision>
      <origin rpy="0 0 0" xyz="0 0 0"/>
      <geometry>
        <mesh filename="package://rabbitamr_description/meshes/caster_wheel/mechanism_top.stl" scale="0.13 0.13 0.13"/>
      </geometry>
    </collision>
    <inertial>
      <mass value="1"/>
      <inertia ixx="0.000358333333333" ixy="0" ixz="0" iyy="0.000358333333333" iyz="0" izz="0.00045"/>
    </inertial>
  </link>
  <joint name="front_right_mechanism_top_joint" type="continuous">
    <axis rpy="0 0 0" xyz="0 0 1"/>
    <parent link="front_right_top_flat"/>
    <child link="front_right_mechanism_top"/>
    <origin rpy="0 0 0" xyz="0 0 0"/>
  </joint>
  <link name="front_right_mechanism_bottom">
    <visual>
      <origin rpy="3.14159265359 0 0" xyz="0 0 0"/>
      <geometry>
        <mesh filename="package://rabbitamr_description/meshes/caster_wheel/mechanism_top.stl" scale="0.13 0.13 0.13"/>
      </geometry>
      <material name="white"/>
    </visual>
    <collision>
      <origin rpy="3.14159265359 0 0" xyz="0 0 0"/>
      <geometry>
        <mesh filename="package://rabbitamr_description/meshes/caster_wheel/mechanism_top.stl" scale="0.13 0.13 0.13"/>
      </geometry>
    </collision>
    <inertial>
      <mass value="1"/>
      <inertia ixx="0.000358333333333" ixy="0" ixz="0" iyy="0.000358333333333" iyz="0" izz="0.00045"/>
    </inertial>
  </link>
  <joint name="front_right_mechanism_bottom_joint" type="fixed">
    <parent link="front_right_mechanism_top"/>
    <child link="front_right_mechanism_bottom"/>
    <origin rpy="0 0 0" xyz="0 0.015 -0.0312"/>
  </joint>
  <link name="front_right_bottom_flat">
    <visual>
      <origin rpy="0 0 0" xyz="0 0 0"/>
      <geometry>
        <mesh filename="package://rabbitamr_description/meshes/caster_wheel/bottom_flat.stl" scale="0.026 0.026 0.026"/>
      </geometry>
      <material name="white"/>
    </visual>
    <collision>
      <origin rpy="0 0 0" xyz="0 0 0"/>
      <geometry>
        <mesh filename="package://rabbitamr_description/meshes/caster_wheel/bottom_flat.stl" scale="0.026 0.026 0.026"/>
      </geometry>
    </collision>
    <inertial>
      <mass value="1"/>
      <inertia ixx="1.66666666667e-07" ixy="0.0" ixz="0.0" iyy="1.66666666667e-07" iyz="0.0" izz="1.66666666667e-07"/>
    </inertial>
  </link>
  <joint name="front_right_bottom_flat_joint" type="continuous">
    <axis rpy="0 0 0" xyz="0 0 1"/>
    <parent link="front_right_mechanism_bottom"/>
    <child link="front_right_bottom_flat"/>
    <origin rpy="0 0 0" xyz="0 0 0.0026"/>
  </joint>
  <link name="front_right_wheel_holder">
    <visual>
      <origin rpy="0 0 0" xyz="0 0 0"/>
      <geometry>
        <mesh filename="package://rabbitamr_description/meshes/caster_wheel/wheel_holder.stl" scale="0.1014 0.1014 0.1014"/>
      </geometry>
      <material name="white"/>
    </visual>
    <collision>
      <origin rpy="0 0 0" xyz="0 0 0"/>
      <geometry>
        <mesh filename="package://rabbitamr_description/meshes/caster_wheel/wheel_holder.stl" scale="0.1014 0.1014 0.1014"/>
      </geometry>
    </collision>
    <inertial>
      <mass value="1"/>
      <inertia ixx="1.66666666667e-07" ixy="0.0" ixz="0.0" iyy="1.66666666667e-07" iyz="0.0" izz="1.66666666667e-07"/>
    </inertial>
  </link>
  <joint name="front_right_wheel_holder_joint" type="fixed">
    <axis rpy="0 0 0" xyz="0 0 1"/>
    <parent link="front_right_bottom_flat"/>
    <child link="front_right_wheel_holder"/>
    <origin rpy="0 0 0" xyz="0 0 -0.0494"/>
  </joint>
  <link name="front_right_caster_wheel">
    <visual>
      <origin rpy="0 0 0" xyz="0 0 0"/>
      <geometry>
        <mesh filename="package://rabbitamr_description/meshes/caster_wheel/caster_wheel.stl" scale="0.1014 0.1014 0.1014"/>
      </geometry>
      <material name="orange"/>
    </visual>
    <collision>
      <origin rpy="1.57079632679 0 0" xyz="0 0 0"/>
      <geometry>
        <cylinder length="0.03" radius="0.05"/>
      </geometry>
    </collision>
    <inertial>
      <mass value="1"/>
      <inertia ixx="0.000358333333333" ixy="0" ixz="0" iyy="0.000358333333333" iyz="0" izz="0.00045"/>
    </inertial>
  </link>
  <joint name="front_right_caster_wheel_joint" type="continuous">
    <axis rpy="0 0 0" xyz="0 1 0"/>
    <parent link="front_right_wheel_holder"/>
    <child link="front_right_caster_wheel"/>
    <origin rpy="0 0 0" xyz="0.0195 0 -0.044525"/>
  </joint>
  <link name="back_left_top_flat">
    <visual>
      <origin rpy="0 0 0" xyz="0 0 0"/>
      <geometry>
        <mesh filename="package://rabbitamr_description/meshes/caster_wheel/top_flat.stl" scale="3.9 3.9 3.9"/>
      </geometry>
      <material name="white"/>
    </visual>
    <collision>
      <origin rpy="0 0 0" xyz="0 0 0"/>
      <geometry>
        <box size="0.15 0.15 0.01"/>
      </geometry>
    </collision>
    <inertial>
      <mass value="1"/>
      <inertia ixx="1.66666666667e-07" ixy="0.0" ixz="0.0" iyy="1.66666666667e-07" iyz="0.0" izz="1.66666666667e-07"/>
    </inertial>
  </link>
  <joint name="back_left_top_flat_joint" type="fixed">
    <parent link="base_link"/>
    <child link="back_left_top_flat"/>
    <origin rpy="0 0 0" xyz="-0.5125 0.239 0.003525"/>
  </joint>
  <link name="back_left_mechanism_top">
    <visual>
      <origin rpy="0 0 0" xyz="0 0 0"/>
      <geometry>
        <mesh filename="package://rabbitamr_description/meshes/caster_wheel/mechanism_top.stl" scale="0.13 0.13 0.13"/>
      </geometry>
      <material name="white"/>
    </visual>
    <collision>
      <origin rpy="0 0 0" xyz="0 0 0"/>
      <geometry>
        <mesh filename="package://rabbitamr_description/meshes/caster_wheel/mechanism_top.stl" scale="0.13 0.13 0.13"/>
      </geometry>
    </collision>
    <inertial>
      <mass value="1"/>
      <inertia ixx="0.000358333333333" ixy="0" ixz="0" iyy="0.000358333333333" iyz="0" izz="0.00045"/>
    </inertial>
  </link>
  <joint name="back_left_mechanism_top_joint" type="continuous">
    <axis rpy="0 0 0" xyz="0 0 1"/>
    <parent link="back_left_top_flat"/>
    <child link="back_left_mechanism_top"/>
    <origin rpy="0 0 0" xyz="0 0 0"/>
  </joint>
  <link name="back_left_mechanism_bottom">
    <visual>
      <origin rpy="3.14159265359 0 0" xyz="0 0 0"/>
      <geometry>
        <mesh filename="package://rabbitamr_description/meshes/caster_wheel/mechanism_top.stl" scale="0.13 0.13 0.13"/>
      </geometry>
      <material name="white"/>
    </visual>
    <collision>
      <origin rpy="3.14159265359 0 0" xyz="0 0 0"/>
      <geometry>
        <mesh filename="package://rabbitamr_description/meshes/caster_wheel/mechanism_top.stl" scale="0.13 0.13 0.13"/>
      </geometry>
    </collision>
    <inertial>
      <mass value="1"/>
      <inertia ixx="0.000358333333333" ixy="0" ixz="0" iyy="0.000358333333333" iyz="0" izz="0.00045"/>
    </inertial>
  </link>
  <joint name="back_left_mechanism_bottom_joint" type="fixed">
    <parent link="back_left_mechanism_top"/>
    <child link="back_left_mechanism_bottom"/>
    <origin rpy="0 0 0" xyz="0 0.015 -0.0312"/>
  </joint>
  <link name="back_left_bottom_flat">
    <visual>
      <origin rpy="0 0 0" xyz="0 0 0"/>
      <geometry>
        <mesh filename="package://rabbitamr_description/meshes/caster_wheel/bottom_flat.stl" scale="0.026 0.026 0.026"/>
      </geometry>
      <material name="white"/>
    </visual>
    <collision>
      <origin rpy="0 0 0" xyz="0 0 0"/>
      <geometry>
        <mesh filename="package://rabbitamr_description/meshes/caster_wheel/bottom_flat.stl" scale="0.026 0.026 0.026"/>
      </geometry>
    </collision>
    <inertial>
      <mass value="1"/>
      <inertia ixx="1.66666666667e-07" ixy="0.0" ixz="0.0" iyy="1.66666666667e-07" iyz="0.0" izz="1.66666666667e-07"/>
    </inertial>
  </link>
  <joint name="back_left_bottom_flat_joint" type="continuous">
    <axis rpy="0 0 0" xyz="0 0 1"/>
    <parent link="back_left_mechanism_bottom"/>
    <child link="back_left_bottom_flat"/>
    <origin rpy="0 0 0" xyz="0 0 0.0026"/>
  </joint>
  <link name="back_left_wheel_holder">
    <visual>
      <origin rpy="0 0 0" xyz="0 0 0"/>
      <geometry>
        <mesh filename="package://rabbitamr_description/meshes/caster_wheel/wheel_holder.stl" scale="0.1014 0.1014 0.1014"/>
      </geometry>
      <material name="white"/>
    </visual>
    <collision>
      <origin rpy="0 0 0" xyz="0 0 0"/>
      <geometry>
        <mesh filename="package://rabbitamr_description/meshes/caster_wheel/wheel_holder.stl" scale="0.1014 0.1014 0.1014"/>
      </geometry>
    </collision>
    <inertial>
      <mass value="1"/>
      <inertia ixx="1.66666666667e-07" ixy="0.0" ixz="0.0" iyy="1.66666666667e-07" iyz="0.0" izz="1.66666666667e-07"/>
    </inertial>
  </link>
  <joint name="back_left_wheel_holder_joint" type="fixed">
    <axis rpy="0 0 0" xyz="0 0 1"/>
    <parent link="back_left_bottom_flat"/>
    <child link="back_left_wheel_holder"/>
    <origin rpy="0 0 0" xyz="0 0 -0.0494"/>
  </joint>
  <link name="back_left_caster_wheel">
    <visual>
      <origin rpy="0 0 0" xyz="0 0 0"/>
      <geometry>
        <mesh filename="package://rabbitamr_description/meshes/caster_wheel/caster_wheel.stl" scale="0.1014 0.1014 0.1014"/>
      </geometry>
      <material name="orange"/>
    </visual>
    <collision>
      <origin rpy="1.57079632679 0 0" xyz="0 0 0"/>
      <geometry>
        <cylinder length="0.03" radius="0.05"/>
      </geometry>
    </collision>
    <inertial>
      <mass value="1"/>
      <inertia ixx="0.000358333333333" ixy="0" ixz="0" iyy="0.000358333333333" iyz="0" izz="0.00045"/>
    </inertial>
  </link>
  <joint name="back_left_caster_wheel_joint" type="continuous">
    <axis rpy="0 0 0" xyz="0 1 0"/>
    <parent link="back_left_wheel_holder"/>
    <child link="back_left_caster_wheel"/>
    <origin rpy="0 0 0" xyz="0.0195 0 -0.044525"/>
  </joint>
  <link name="back_right_top_flat">
    <visual>
      <origin rpy="0 0 0" xyz="0 0 0"/>
      <geometry>
        <mesh filename="package://rabbitamr_description/meshes/caster_wheel/top_flat.stl" scale="3.9 3.9 3.9"/>
      </geometry>
      <material name="white"/>
    </visual>
    <collision>
      <origin rpy="0 0 0" xyz="0 0 0"/>
      <geometry>
        <box size="0.15 0.15 0.01"/>
      </geometry>
    </collision>
    <inertial>
      <mass value="1"/>
      <inertia ixx="1.66666666667e-07" ixy="0.0" ixz="0.0" iyy="1.66666666667e-07" iyz="0.0" izz="1.66666666667e-07"/>
    </inertial>
  </link>
  <joint name="back_right_top_flat_joint" type="fixed">
    <parent link="base_link"/>
    <child link="back_right_top_flat"/>
    <origin rpy="0 0 0" xyz="-0.5125 -0.239 0.003525"/>
  </joint>
  <link name="back_right_mechanism_top">
    <visual>
      <origin rpy="0 0 0" xyz="0 0 0"/>
      <geometry>
        <mesh filename="package://rabbitamr_description/meshes/caster_wheel/mechanism_top.stl" scale="0.13 0.13 0.13"/>
      </geometry>
      <material name="white"/>
    </visual>
    <collision>
      <origin rpy="0 0 0" xyz="0 0 0"/>
      <geometry>
        <mesh filename="package://rabbitamr_description/meshes/caster_wheel/mechanism_top.stl" scale="0.13 0.13 0.13"/>
      </geometry>
    </collision>
    <inertial>
      <mass value="1"/>
      <inertia ixx="0.000358333333333" ixy="0" ixz="0" iyy="0.000358333333333" iyz="0" izz="0.00045"/>
    </inertial>
  </link>
  <joint name="back_right_mechanism_top_joint" type="continuous">
    <axis rpy="0 0 0" xyz="0 0 1"/>
    <parent link="back_right_top_flat"/>
    <child link="back_right_mechanism_top"/>
    <origin rpy="0 0 0" xyz="0 0 0"/>
  </joint>
  <link name="back_right_mechanism_bottom">
    <visual>
      <origin rpy="3.14159265359 0 0" xyz="0 0 0"/>
      <geometry>
        <mesh filename="package://rabbitamr_description/meshes/caster_wheel/mechanism_top.stl" scale="0.13 0.13 0.13"/>
      </geometry>
      <material name="white"/>
    </visual>
    <collision>
      <origin rpy="3.14159265359 0 0" xyz="0 0 0"/>
      <geometry>
        <mesh filename="package://rabbitamr_description/meshes/caster_wheel/mechanism_top.stl" scale="0.13 0.13 0.13"/>
      </geometry>
    </collision>
    <inertial>
      <mass value="1"/>
      <inertia ixx="0.000358333333333" ixy="0" ixz="0" iyy="0.000358333333333" iyz="0" izz="0.00045"/>
    </inertial>
  </link>
  <joint name="back_right_mechanism_bottom_joint" type="fixed">
    <parent link="back_right_mechanism_top"/>
    <child link="back_right_mechanism_bottom"/>
    <origin rpy="0 0 0" xyz="0 0.015 -0.0312"/>
  </joint>
  <link name="back_right_bottom_flat">
    <visual>
      <origin rpy="0 0 0" xyz="0 0 0"/>
      <geometry>
        <mesh filename="package://rabbitamr_description/meshes/caster_wheel/bottom_flat.stl" scale="0.026 0.026 0.026"/>
      </geometry>
      <material name="white"/>
    </visual>
    <collision>
      <origin rpy="0 0 0" xyz="0 0 0"/>
      <geometry>
        <mesh filename="package://rabbitamr_description/meshes/caster_wheel/bottom_flat.stl" scale="0.026 0.026 0.026"/>
      </geometry>
    </collision>
    <inertial>
      <mass value="1"/>
      <inertia ixx="1.66666666667e-07" ixy="0.0" ixz="0.0" iyy="1.66666666667e-07" iyz="0.0" izz="1.66666666667e-07"/>
    </inertial>
  </link>
  <joint name="back_right_bottom_flat_joint" type="continuous">
    <axis rpy="0 0 0" xyz="0 0 1"/>
    <parent link="back_right_mechanism_bottom"/>
    <child link="back_right_bottom_flat"/>
    <origin rpy="0 0 0" xyz="0 0 0.0026"/>
  </joint>
  <link name="back_right_wheel_holder">
    <visual>
      <origin rpy="0 0 0" xyz="0 0 0"/>
      <geometry>
        <mesh filename="package://rabbitamr_description/meshes/caster_wheel/wheel_holder.stl" scale="0.1014 0.1014 0.1014"/>
      </geometry>
      <material name="white"/>
    </visual>
    <collision>
      <origin rpy="0 0 0" xyz="0 0 0"/>
      <geometry>
        <mesh filename="package://rabbitamr_description/meshes/caster_wheel/wheel_holder.stl" scale="0.1014 0.1014 0.1014"/>
      </geometry>
    </collision>
    <inertial>
      <mass value="1"/>
      <inertia ixx="1.66666666667e-07" ixy="0.0" ixz="0.0" iyy="1.66666666667e-07" iyz="0.0" izz="1.66666666667e-07"/>
    </inertial>
  </link>
  <joint name="back_right_wheel_holder_joint" type="fixed">
    <axis rpy="0 0 0" xyz="0 0 1"/>
    <parent link="back_right_bottom_flat"/>
    <child link="back_right_wheel_holder"/>
    <origin rpy="0 0 0" xyz="0 0 -0.0494"/>
  </joint>
  <link name="back_right_caster_wheel">
    <visual>
      <origin rpy="0 0 0" xyz="0 0 0"/>
      <geometry>
        <mesh filename="package://rabbitamr_description/meshes/caster_wheel/caster_wheel.stl" scale="0.1014 0.1014 0.1014"/>
      </geometry>
      <material name="orange"/>
    </visual>
    <collision>
      <origin rpy="1.57079632679 0 0" xyz="0 0 0"/>
      <geometry>
        <cylinder length="0.03" radius="0.05"/>
      </geometry>
    </collision>
    <inertial>
      <mass value="1"/>
      <inertia ixx="0.000358333333333" ixy="0" ixz="0" iyy="0.000358333333333" iyz="0" izz="0.00045"/>
    </inertial>
  </link>
  <joint name="back_right_caster_wheel_joint" type="continuous">
    <axis rpy="0 0 0" xyz="0 1 0"/>
    <parent link="back_right_wheel_holder"/>
    <child link="back_right_caster_wheel"/>
    <origin rpy="0 0 0" xyz="0.0195 0 -0.044525"/>
  </joint>
  <link name="sicklidar">
    <visual>
      <origin rpy="3.14159265359 0 0" xyz="0 0 0.07"/>
      <geometry>
        <mesh filename="package://rabbitamr_description/meshes/accessories/laser_scanner.stl" scale="0.0025 0.0025 0.0025"/>
      </geometry>
      <material name="black"/>
    </visual>
    <collision>
      <origin rpy="3.14159265359 0 0" xyz="0 0 0"/>
      <geometry>
        <box size="0.1 0.1 0.18"/>
      </geometry>
    </collision>
    <inertial>
      <mass value="0.2"/>
      <inertia ixx="0.000706666666667" ixy="0.0" ixz="0.0" iyy="0.000333333333333" iyz="0.0" izz="0.000706666666667"/>
    </inertial>
  </link>
  <joint name="sicklidar_joint" type="fixed">
    <origin rpy="0 0 0" xyz="0.72 0 -0.045"/>
    <parent link="base_link"/>
    <child link="sicklidar"/>
  </joint>
  <link name="d435i">
    <visual>
      <origin rpy="1.57079632679 0 1.57079632679" xyz="0 0 0"/>
      <geometry>
        <mesh filename="package://rabbitamr_description/meshes/accessories/d435i.dae" scale="1.0 1.0 1.0"/>
      </geometry>
      <material name="black"/>
    </visual>
    <collision>
      <origin rpy="0 0 0" xyz="0 0 0"/>
      <geometry>
        <box size="0.03 0.1 0.03"/>
      </geometry>
    </collision>
    <inertial>
      <mass value="0.1"/>
      <inertia ixx="9.08333333333e-05" ixy="0.0" ixz="0.0" iyy="9.08333333333e-05" iyz="0.0" izz="1.5e-05"/>
    </inertial>
  </link>
  <joint name="d435i_joint" type="fixed">
    <origin rpy="0 0 3.14159265359" xyz="-0.82 0 0.0725"/>
    <parent link="base_link"/>
    <child link="d435i"/>
  </joint>
</robot>

